<?xml version="1.0" ?>
<!-- =================================================================================== -->
<!-- |    This document was autogenerated by xacro from /home/kanishq/arkermann_ws/src/sim_car/car_description/robot/car.urdf.xacro | -->
<!-- |    EDITING THIS FILE BY HAND IS NOT RECOMMENDED                                 | -->
<!-- =================================================================================== -->
<robot name="car">
  <link name="base_footprint"/>
  <link name="base_link"/>
  <!--
  <link name="base_link">
    <visual>
      <origin xyz="0 0 0.1" rpy="0 0 0"/>
      <geometry>
        <cylinder length="0.2" radius="0.01"/>
      </geometry>
      <material name="silver">
        <color rgba="0.75 0.75 0.75 1"/>
      </material>
    </visual>
    <collision>
      <origin xyz="0 0 0.1" rpy="0 0 0"/>
      <geometry>
        <cylinder length="0.2" radius="0.01"/>
      </geometry>
    </collision>
    <inertial>
      <mass value="0.01"/>
      <inertia ixx="0.015" iyy="0.0375" izz="0.0375"
               ixy="0" ixz="0" iyz="0"/>
    </inertial>
  </link>
-->
<gazebo reference="base_link">
  <sensor name="imu_sensor" type="imu">
    <always_on>true</always_on>
    <update_rate>70</update_rate>
    <visualize>true</visualize>

    <plugin name="imu_plugin" filename="libgazebo_ros_imu_sensor.so">
      <ros>
        <namespace>/</namespace>
        <remapping>imu:=imu/data</remapping>
      </ros>
      <frame_name>base_link</frame_name>
    </plugin>
  </sensor>
</gazebo>

  <link name="chassis_link">
    <visual>
      <geometry>
        <box size="0.3429 0.25 0.06"/>
      </geometry>
    </visual>
    <collision>
      <geometry>
        <box size="0.3429 0.25 0.06"/>
      </geometry>
    </collision>
    <inertial>
      <mass value="2.6"/>
      <inertia ixx="0.014321666666666668" ixy="0" ixz="0" iyy="0.026255755499999995" iyz="0" izz="0.026255755499999995"/>
    </inertial>
  </link>
  <link name="back_left_wheel">
    <visual>
      <geometry>
        <cylinder length="0.047" radius="0.056"/>
      </geometry>
      <material name="black">
        <color rgba="0 0 0 1"/>
      </material>
    </visual>
    <collision>
      <geometry>
        <cylinder length="0.047" radius="0.056"/>
      </geometry>
    </collision>
    <inertial>
      <mass value="0.1"/>
      <inertia ixx="9.680833333333336e-05" ixy="0" ixz="0" iyy="9.680833333333336e-05" iyz="0" izz="0.00015680000000000002"/>
    </inertial>
  </link>
  <link name="laser_scanner_link">
    <collision>
      <origin rpy="0 0 0" xyz="0 0 0"/>
      <geometry>
        <box size=".127 0.1016 0.0508"/>
      </geometry>
    </collision>
    <visual>
      <origin rpy="0 0 0" xyz="0 0 0"/>
      <geometry>
        <box size=".127 0.1016 0.0508"/>
      </geometry>
    </visual>
    <inertial>
      <mass value="1e-5"/>
      <origin rpy="0 0 0" xyz="0 0 0"/>
      <inertia ixx="1e-6" ixy="0" ixz="0" iyy="1e-6" iyz="0" izz="1e-6"/>
    </inertial>
  </link>
  <gazebo reference="laser_scanner_link">
  <sensor name="laser_scanner" type="ray">
    <always_on>true</always_on>
    <update_rate>10</update_rate>
    <visualize>true</visualize>

    <ray>
      <scan>
        <horizontal>
          <samples>360</samples>
          <resolution>1</resolution>
          <min_angle>-3.141592653589793</min_angle>
          <max_angle>3.141592653589793</max_angle>
        </horizontal>
      </scan>

      <range>
        <min>0.30</min>
        <max>25.0</max>
        <resolution>0.1</resolution>
      </range>
    </ray>

    <plugin name="laser_plugin" filename="libgazebo_ros_ray_sensor.so">
      <ros>
        <namespace>/</namespace>
        <remapping>~/out:=scan</remapping>
      </ros>
      <output_type>sensor_msgs/LaserScan</output_type>
      <frame_name>laser_scanner_link</frame_name>
    </plugin>
  </sensor>
</gazebo>


  <link name="back_right_wheel">
    <visual>
      <geometry>
        <cylinder length="0.047" radius="0.056"/>
      </geometry>
      <material name="black">
        <color rgba="0 0 0 1"/>
      </material>
    </visual>
    <collision>
      <geometry>
        <cylinder length="0.047" radius="0.056"/>
      </geometry>
    </collision>
    <inertial>
      <mass value="0.1"/>
      <inertia ixx="9.680833333333336e-05" ixy="0" ixz="0" iyy="9.680833333333336e-05" iyz="0" izz="0.00015680000000000002"/>
    </inertial>
  </link>
  <link name="front_left_wheel_steer">
    <visual>
      <geometry>
        <cylinder length="0.01" radius="0.01"/>
      </geometry>
      <material name="black">
        <color rgba="0 0 0 1"/>
      </material>
    </visual>
    <collision>
      <geometry>
        <cylinder length="0.01" radius="0.01"/>
      </geometry>
    </collision>
    <inertial>
      <mass value="0.1"/>
      <inertia ixx="5.1458e-5" ixy="0" ixz="0" iyy="5.1458e-5" iyz="0" izz="6.125e-5"/>
    </inertial>
  </link>
  <link name="front_left_wheel">
    <visual>
      <geometry>
        <cylinder length="0.047" radius="0.056"/>
      </geometry>
      <material name="black">
        <color rgba="0 0 0 1"/>
      </material>
    </visual>
    <collision>
      <geometry>
        <cylinder length="0.047" radius="0.056"/>
      </geometry>
    </collision>
    <inertial>
      <mass value="0.1"/>
      <inertia ixx="9.680833333333336e-05" ixy="0" ixz="0" iyy="9.680833333333336e-05" iyz="0" izz="0.00015680000000000002"/>
    </inertial>
  </link>
  <link name="front_right_wheel_steer">
    <visual>
      <geometry>
        <cylinder length="0.01" radius="0.01"/>
      </geometry>
      <material name="black">
        <color rgba="0 0 0 1"/>
      </material>
    </visual>
    <collision>
      <geometry>
        <cylinder length="0.01" radius="0.01"/>
      </geometry>
    </collision>
    <inertial>
      <mass value="0.1"/>
      <inertia ixx="5.1458e-5" ixy="0" ixz="0" iyy="5.1458e-5" iyz="0" izz="6.125e-5"/>
    </inertial>
  </link>
  <link name="front_right_wheel">
    <visual>
      <geometry>
        <cylinder length="0.047" radius="0.056"/>
      </geometry>
      <material name="black">
        <color rgba="0 0 0 1"/>
      </material>
    </visual>
    <collision>
      <geometry>
        <cylinder length="0.047" radius="0.056"/>
      </geometry>
    </collision>
    <inertial>
      <mass value="0.1"/>
      <inertia ixx="9.680833333333336e-05" ixy="0" ixz="0" iyy="9.680833333333336e-05" iyz="0" izz="0.00015680000000000002"/>
    </inertial>
  </link>
  <link name="back_left_wheel_shock">
    <visual>
      <origin rpy="0 0 0" xyz="0 0 0.1"/>
      <geometry>
        <cylinder length="0.05" radius="0.01"/>
      </geometry>
      <material name="silver">
        <color rgba="0.75 0.75 0.75 1"/>
      </material>
    </visual>
    <collision>
      <origin rpy="0 0 0" xyz="0 0 0.1"/>
      <geometry>
        <cylinder length="0.05" radius="0.01"/>
      </geometry>
    </collision>
    <inertial>
      <mass value="0.01"/>
      <inertia ixx="0.015" ixy="0" ixz="0" iyy="0.0375" iyz="0" izz="0.0375"/>
    </inertial>
  </link>
  <link name="back_right_wheel_shock">
    <visual>
      <origin rpy="0 0 0" xyz="0 0 0.1"/>
      <geometry>
        <cylinder length="0.05" radius="0.01"/>
      </geometry>
      <material name="silver">
        <color rgba="0.75 0.75 0.75 1"/>
      </material>
    </visual>
    <collision>
      <origin rpy="0 0 0" xyz="0 0 0.1"/>
      <geometry>
        <cylinder length="0.05" radius="0.01"/>
      </geometry>
    </collision>
    <inertial>
      <mass value="0.01"/>
      <inertia ixx="0.015" ixy="0" ixz="0" iyy="0.0375" iyz="0" izz="0.0375"/>
    </inertial>
  </link>
  <link name="front_left_wheel_shock">
    <visual>
      <origin rpy="0 0 0" xyz="0 0 0.1"/>
      <geometry>
        <cylinder length="0.05" radius="0.01"/>
      </geometry>
      <material name="silver">
        <color rgba="0.75 0.75 0.75 1"/>
      </material>
    </visual>
    <collision>
      <origin rpy="0 0 0" xyz="0 0 0.1"/>
      <geometry>
        <cylinder length="0.05" radius="0.01"/>
      </geometry>
    </collision>
    <inertial>
      <mass value="0.01"/>
      <inertia ixx="0.015" ixy="0" ixz="0" iyy="0.0375" iyz="0" izz="0.0375"/>
    </inertial>
  </link>
  <link name="front_right_wheel_shock">
    <visual>
      <origin rpy="0 0 0" xyz="0 0 0.1"/>
      <geometry>
        <cylinder length="0.05" radius="0.01"/>
      </geometry>
      <material name="silver">
        <color rgba="0.75 0.75 0.75 1"/>
      </material>
    </visual>
    <collision>
      <origin rpy="0 0 0" xyz="0 0 0.1"/>
      <geometry>
        <cylinder length="0.05" radius="0.01"/>
      </geometry>
    </collision>
    <inertial>
      <mass value="0.01"/>
      <inertia ixx="0.015" ixy="0" ixz="0" iyy="0.0375" iyz="0" izz="0.0375"/>
    </inertial>
  </link>
  <joint name="base_link_joint" type="fixed">
    <parent link="base_footprint"/>
    <child link="base_link"/>
    <origin rpy="0 0 0" xyz="0 0 0"/>
  </joint>
  <joint name="laser_scanner_joint" type="fixed">
    <origin rpy="0 0 0" xyz="0.1397 0 0.2159"/>
    <parent link="base_link"/>
    <child link="laser_scanner_link"/>
  </joint>
  <joint name="back_left_shock_joint" type="prismatic">
    <limit effort="100" lower="0" upper="0.09" velocity="100"/>
    <axis xyz="0 0 1"/>
    <parent link="base_link"/>
    <child link="back_left_wheel_shock"/>
    <origin rpy="0 0 0" xyz="0 0.125  -0.045"/>
  </joint>
  <joint name="back_left_wheel_joint" type="continuous">
    <axis xyz="0 0 1"/>
    <parent link="back_left_wheel_shock"/>
    <child link="back_left_wheel"/>
    <origin rpy="-1.5707963267948966 0 0" xyz="0 0 0"/>
    <limit effort="10000" velocity="500"/>
  </joint>
  <joint name="back_right_shock_joint" type="prismatic">
    <limit effort="100" lower="0" upper="0.09" velocity="100"/>
    <axis xyz="0 0 1"/>
    <parent link="base_link"/>
    <child link="back_right_wheel_shock"/>
    <origin rpy="0 0 0" xyz="0 -0.125 -0.045"/>
  </joint>
  <joint name="back_right_wheel_joint" type="continuous">
    <axis xyz="0 0 1"/>
    <parent link="back_right_wheel_shock"/>
    <child link="back_right_wheel"/>
    <origin rpy="-1.5707963267948966 0 0" xyz="0 0 0"/>
    <limit effort="10000" velocity="500"/>
  </joint>
  <joint name="front_right_shock_joint" type="prismatic">
    <limit effort="100" lower="0" upper="0.09" velocity="100"/>
    <axis xyz="0 0 1"/>
    <parent link="base_link"/>
    <child link="front_right_wheel_shock"/>
    <origin rpy="0 0 0" xyz="0.3429 -0.125 -0.045"/>
  </joint>
  <joint name="front_left_shock_joint" type="prismatic">
    <limit effort="100" lower="0" upper="0.09" velocity="100"/>
    <axis xyz="0 0 1"/>
    <parent link="base_link"/>
    <child link="front_left_wheel_shock"/>
    <origin rpy="0 0 0" xyz="0.3429 0.125  -0.045"/>
  </joint>
  <joint name="front_left_wheel_steer_joint" type="revolute">
    <limit effort="1" lower="-1" upper="1" velocity="5"/>
    <axis xyz="0 0 1"/>
    <parent link="front_left_wheel_shock"/>
    <child link="front_left_wheel_steer"/>
    <origin rpy="0 0 0" xyz="0 0 0"/>
  </joint>
  <joint name="front_left_wheel_joint" type="continuous">
    <axis xyz="0 0 1"/>
    <parent link="front_left_wheel_steer"/>
    <child link="front_left_wheel"/>
    <origin rpy="-1.5707963267948966 0 0" xyz="0 0 0"/>
  </joint>
  <joint name="front_right_wheel_steer_joint" type="revolute">
    <limit effort="1" lower="-1" upper="1" velocity="5"/>
    <axis xyz="0 0 1"/>
    <parent link="front_right_wheel_shock"/>
    <child link="front_right_wheel_steer"/>
    <origin rpy="0 0 0" xyz="0 0 0"/>
  </joint>
  <joint name="front_right_wheel_joint" type="continuous">
    <axis xyz="0 0 1"/>
    <parent link="front_right_wheel_steer"/>
    <child link="front_right_wheel"/>
    <origin rpy="-1.5707963267948966 0 0" xyz="0 0 0"/>
  </joint>
  <joint name="chassis_joint" type="fixed">
    <parent link="base_link"/>
    <child link="chassis_link"/>
    <origin rpy="0 0 0" xyz="0.17145 0 0.019999999999999997"/>
  </joint>
  <gazebo reference="front_left_wheel">
    <mu1>0.8</mu1>
    <material>Gazebo/DarkGrey</material>
  </gazebo>
  <gazebo reference="front_right_wheel">
    <mu1>0.8</mu1>
    <material>Gazebo/DarkGrey</material>
  </gazebo>
  <gazebo reference="back_left_wheel">
    <mu1>0.8</mu1>
    <material>Gazebo/DarkGrey</material>
  </gazebo>
  <gazebo reference="back_right_wheel">
    <mu1>0.8</mu1>
    <material>Gazebo/DarkGrey</material>
  </gazebo>
  <gazebo reference="base_link">
    <dampingFactor>0.00007</dampingFactor>
  </gazebo>
  <gazebo>
    <plugin filename="libcar_gazebo_plugin.so" name="car_gazebo_plugin">
    </plugin>
  </gazebo>
</robot>
